Workbook

Sheet Summary
A1: OWASP ASVS 5.0 – Compliance Tracker
A5: Chapter | B5: Total Reqs | C5: L1 Total | D5: L1 Compliant | E5: L1 % | F5: L2 Total | G5: L2 Compliant | H5: L2 % | I5: L3 Total | J5: L3 Compliant | K5: L3 % | L5: Overall Compliant | M5: Overall %
A6: V1 – Encoding and Sanitization | B6: 30 | C6: 8 | D6: =COUNTIFS('V1 - Encoding and Sanitization'!$F$2:$F$36,"Compliant",'V1 - Encoding and Sanitization'!$E$2:$E$36,1) -> 4 | E6: =IF(C6=0,"",D6/C6) -> 0.5 | F6: 19 | G6: =COUNTIFS('V1 - Encoding and Sanitization'!$F$2:$F$36,"Compliant",'V1 - Encoding and Sanitization'!$E$2:$E$36,2) -> 11 | H6: =IF(F6=0,"",G6/F6) -> 0.57894737 | I6: 3 | J6: =COUNTIFS('V1 - Encoding and Sanitization'!$F$2:$F$36,"Compliant",'V1 - Encoding and Sanitization'!$E$2:$E$36,3) -> 2 | K6: =IF(I6=0,"",J6/I6) -> 0.66666667 | L6: =COUNTIF('V1 - Encoding and Sanitization'!$F$2:$F$36,"Compliant") -> 17 | M6: =IF(B6=0,"",L6/B6) -> 0.56666667
A7: V2 – Validation and Business Logic | B7: 13 | C7: 4 | D7: =COUNTIFS('V2 - Validation and Business Lo'!$F$2:$F$18,"Compliant",'V2 - Validation and Business Lo'!$E$2:$E$18,1) -> 4 | E7: =IF(C7=0,"",D7/C7) -> 1 | F7: 7 | G7: =COUNTIFS('V2 - Validation and Business Lo'!$F$2:$F$18,"Compliant",'V2 - Validation and Business Lo'!$E$2:$E$18,2) -> 6 | H7: =IF(F7=0,"",G7/F7) -> 0.85714286 | I7: 2 | J7: =COUNTIFS('V2 - Validation and Business Lo'!$F$2:$F$18,"Compliant",'V2 - Validation and Business Lo'!$E$2:$E$18,3) -> 1 | K7: =IF(I7=0,"",J7/I7) -> 0.5 | L7: =COUNTIF('V2 - Validation and Business Lo'!$F$2:$F$18,"Compliant") -> 11 | M7: =IF(B7=0,"",L7/B7) -> 0.84615385
A8: V3 – Web Frontend Security | B8: 31 | C8: 8 | D8: =COUNTIFS('V3 - Web Frontend Security'!$F$2:$F$39,"Compliant",'V3 - Web Frontend Security'!$E$2:$E$39,1) -> 0 | E8: =IF(C8=0,"",D8/C8) -> 0 | F8: 11 | G8: =COUNTIFS('V3 - Web Frontend Security'!$F$2:$F$39,"Compliant",'V3 - Web Frontend Security'!$E$2:$E$39,2) -> 0 | H8: =IF(F8=0,"",G8/F8) -> 0 | I8: 12 | J8: =COUNTIFS('V3 - Web Frontend Security'!$F$2:$F$39,"Compliant",'V3 - Web Frontend Security'!$E$2:$E$39,3) -> 0 | K8: =IF(I8=0,"",J8/I8) -> 0 | L8: =COUNTIF('V3 - Web Frontend Security'!$F$2:$F$39,"Compliant") -> 0 | M8: =IF(B8=0,"",L8/B8) -> 0
A9: V4 – API and Web Service | B9: 16 | C9: 2 | D9: =COUNTIFS('V4 - API and Web Service'!$F$2:$F$21,"Compliant",'V4 - API and Web Service'!$E$2:$E$21,1) -> 1 | E9: =IF(C9=0,"",D9/C9) -> 0.5 | F9: 8 | G9: =COUNTIFS('V4 - API and Web Service'!$F$2:$F$21,"Compliant",'V4 - API and Web Service'!$E$2:$E$21,2) -> 2 | H9: =IF(F9=0,"",G9/F9) -> 0.25 | I9: 6 | J9: =COUNTIFS('V4 - API and Web Service'!$F$2:$F$21,"Compliant",'V4 - API and Web Service'!$E$2:$E$21,3) -> 6 | K9: =IF(I9=0,"",J9/I9) -> 1 | L9: =COUNTIF('V4 - API and Web Service'!$F$2:$F$21,"Compliant") -> 9 | M9: =IF(B9=0,"",L9/B9) -> 0.5625
A10: V5 – File Handling | B10: 13 | C10: 4 | D10: =COUNTIFS('V5 - File Handling'!$F$2:$F$18,"Compliant",'V5 - File Handling'!$E$2:$E$18,1) -> 4 | E10: =IF(C10=0,"",D10/C10) -> 1 | F10: 5 | G10: =COUNTIFS('V5 - File Handling'!$F$2:$F$18,"Compliant",'V5 - File Handling'!$E$2:$E$18,2) -> 5 | H10: =IF(F10=0,"",G10/F10) -> 1 | I10: 4 | J10: =COUNTIFS('V5 - File Handling'!$F$2:$F$18,"Compliant",'V5 - File Handling'!$E$2:$E$18,3) -> 3 | K10: =IF(I10=0,"",J10/I10) -> 0.75 | L10: =COUNTIF('V5 - File Handling'!$F$2:$F$18,"Compliant") -> 12 | M10: =IF(B10=0,"",L10/B10) -> 0.92307692
A11: V6 – Authentication | B11: 47 | C11: 13 | D11: =COUNTIFS('V6 - Authentication'!$F$2:$F$56,"Compliant",'V6 - Authentication'!$E$2:$E$56,1) -> 12 | E11: =IF(C11=0,"",D11/C11) -> 0.92307692 | F11: 22 | G11: =COUNTIFS('V6 - Authentication'!$F$2:$F$56,"Compliant",'V6 - Authentication'!$E$2:$E$56,2) -> 11 | H11: =IF(F11=0,"",G11/F11) -> 0.5 | I11: 12 | J11: =COUNTIFS('V6 - Authentication'!$F$2:$F$56,"Compliant",'V6 - Authentication'!$E$2:$E$56,3) -> 7 | K11: =IF(I11=0,"",J11/I11) -> 0.58333333 | L11: =COUNTIF('V6 - Authentication'!$F$2:$F$56,"Compliant") -> 30 | M11: =IF(B11=0,"",L11/B11) -> 0.63829787
A12: V7 – Session Management | B12: 19 | C12: 6 | D12: =COUNTIFS('V7 - Session Management'!$F$2:$F$26,"Compliant",'V7 - Session Management'!$E$2:$E$26,1) -> 6 | E12: =IF(C12=0,"",D12/C12) -> 1 | F12: 12 | G12: =COUNTIFS('V7 - Session Management'!$F$2:$F$26,"Compliant",'V7 - Session Management'!$E$2:$E$26,2) -> 6 | H12: =IF(F12=0,"",G12/F12) -> 0.5 | I12: 1 | J12: =COUNTIFS('V7 - Session Management'!$F$2:$F$26,"Compliant",'V7 - Session Management'!$E$2:$E$26,3) -> 0 | K12: =IF(I12=0,"",J12/I12) -> 0 | L12: =COUNTIF('V7 - Session Management'!$F$2:$F$26,"Compliant") -> 12 | M12: =IF(B12=0,"",L12/B12) -> 0.63157895
A13: V8 – Authorization | B13: 13 | C13: 4 | D13: =COUNTIFS('V8 - Authorization'!$F$2:$F$18,"Compliant",'V8 - Authorization'!$E$2:$E$18,1) -> 3 | E13: =IF(C13=0,"",D13/C13) -> 0.75 | F13: 3 | G13: =COUNTIFS('V8 - Authorization'!$F$2:$F$18,"Compliant",'V8 - Authorization'!$E$2:$E$18,2) -> 2 | H13: =IF(F13=0,"",G13/F13) -> 0.66666667 | I13: 6 | J13: =COUNTIFS('V8 - Authorization'!$F$2:$F$18,"Compliant",'V8 - Authorization'!$E$2:$E$18,3) -> 3 | K13: =IF(I13=0,"",J13/I13) -> 0.5 | L13: =COUNTIF('V8 - Authorization'!$F$2:$F$18,"Compliant") -> 8 | M13: =IF(B13=0,"",L13/B13) -> 0.61538462
A14: V9 – Self-contained Tokens | B14: 7 | C14: 4 | D14: =COUNTIFS('V9 - Self-contained Tokens'!$F$2:$F$10,"Compliant",'V9 - Self-contained Tokens'!$E$2:$E$10,1) -> 4 | E14: =IF(C14=0,"",D14/C14) -> 1 | F14: 3 | G14: =COUNTIFS('V9 - Self-contained Tokens'!$F$2:$F$10,"Compliant",'V9 - Self-contained Tokens'!$E$2:$E$10,2) -> 2 | H14: =IF(F14=0,"",G14/F14) -> 0.66666667 | I14: 0 | J14: =COUNTIFS('V9 - Self-contained Tokens'!$F$2:$F$10,"Compliant",'V9 - Self-contained Tokens'!$E$2:$E$10,3) -> 0 | K14: =IF(I14=0,"",J14/I14) | L14: =COUNTIF('V9 - Self-contained Tokens'!$F$2:$F$10,"Compliant") -> 6 | M14: =IF(B14=0,"",L14/B14) -> 0.85714286
A15: V10 – OAuth and OIDC | B15: 36 | C15: 5 | D15: =COUNTIFS('V10 - OAuth and OIDC'!$F$2:$F$44,"Compliant",'V10 - OAuth and OIDC'!$E$2:$E$44,1) -> 2 | E15: =IF(C15=0,"",D15/C15) -> 0.4 | F15: 24 | G15: =COUNTIFS('V10 - OAuth and OIDC'!$F$2:$F$44,"Compliant",'V10 - OAuth and OIDC'!$E$2:$E$44,2) -> 3 | H15: =IF(F15=0,"",G15/F15) -> 0.125 | I15: 7 | J15: =COUNTIFS('V10 - OAuth and OIDC'!$F$2:$F$44,"Compliant",'V10 - OAuth and OIDC'!$E$2:$E$44,3) -> 0 | K15: =IF(I15=0,"",J15/I15) -> 0 | L15: =COUNTIF('V10 - OAuth and OIDC'!$F$2:$F$44,"Compliant") -> 5 | M15: =IF(B15=0,"",L15/B15) -> 0.13888889
A16: V11 – Cryptography | B16: 24 | C16: 3 | D16: =COUNTIFS('V11 - Cryptography'!$F$2:$F$32,"Compliant",'V11 - Cryptography'!$E$2:$E$32,1) -> 3 | E16: =IF(C16=0,"",D16/C16) -> 1 | F16: 11 | G16: =COUNTIFS('V11 - Cryptography'!$F$2:$F$32,"Compliant",'V11 - Cryptography'!$E$2:$E$32,2) -> 11 | H16: =IF(F16=0,"",G16/F16) -> 1 | I16: 10 | J16: =COUNTIFS('V11 - Cryptography'!$F$2:$F$32,"Compliant",'V11 - Cryptography'!$E$2:$E$32,3) -> 8 | K16: =IF(I16=0,"",J16/I16) -> 0.8 | L16: =COUNTIF('V11 - Cryptography'!$F$2:$F$32,"Compliant") -> 22 | M16: =IF(B16=0,"",L16/B16) -> 0.91666667
A17: V12 – Secure Communication | B17: 12 | C17: 3 | D17: =COUNTIFS('V12 - Secure Communication'!$F$2:$F$16,"Compliant",'V12 - Secure Communication'!$E$2:$E$16,1) -> 3 | E17: =IF(C17=0,"",D17/C17) -> 1 | F17: 6 | G17: =COUNTIFS('V12 - Secure Communication'!$F$2:$F$16,"Compliant",'V12 - Secure Communication'!$E$2:$E$16,2) -> 5 | H17: =IF(F17=0,"",G17/F17) -> 0.83333333 | I17: 3 | J17: =COUNTIFS('V12 - Secure Communication'!$F$2:$F$16,"Compliant",'V12 - Secure Communication'!$E$2:$E$16,3) -> 2 | K17: =IF(I17=0,"",J17/I17) -> 0.66666667 | L17: =COUNTIF('V12 - Secure Communication'!$F$2:$F$16,"Compliant") -> 10 | M17: =IF(B17=0,"",L17/B17) -> 0.83333333
A18: V13 – Configuration | B18: 21 | C18: 1 | D18: =COUNTIFS('V13 - Configuration'!$F$2:$F$26,"Compliant",'V13 - Configuration'!$E$2:$E$26,1) -> 1 | E18: =IF(C18=0,"",D18/C18) -> 1 | F18: 12 | G18: =COUNTIFS('V13 - Configuration'!$F$2:$F$26,"Compliant",'V13 - Configuration'!$E$2:$E$26,2) -> 12 | H18: =IF(F18=0,"",G18/F18) -> 1 | I18: 8 | J18: =COUNTIFS('V13 - Configuration'!$F$2:$F$26,"Compliant",'V13 - Configuration'!$E$2:$E$26,3) -> 8 | K18: =IF(I18=0,"",J18/I18) -> 1 | L18: =COUNTIF('V13 - Configuration'!$F$2:$F$26,"Compliant") -> 21 | M18: =IF(B18=0,"",L18/B18) -> 1
A19: V14 – Data Protection | B19: 13 | C19: 2 | D19: =COUNTIFS('V14 - Data Protection'!$F$2:$F$17,"Compliant",'V14 - Data Protection'!$E$2:$E$17,1) -> 1 | E19: =IF(C19=0,"",D19/C19) -> 0.5 | F19: 7 | G19: =COUNTIFS('V14 - Data Protection'!$F$2:$F$17,"Compliant",'V14 - Data Protection'!$E$2:$E$17,2) -> 5 | H19: =IF(F19=0,"",G19/F19) -> 0.71428571 | I19: 4 | J19: =COUNTIFS('V14 - Data Protection'!$F$2:$F$17,"Compliant",'V14 - Data Protection'!$E$2:$E$17,3) -> 2 | K19: =IF(I19=0,"",J19/I19) -> 0.5 | L19: =COUNTIF('V14 - Data Protection'!$F$2:$F$17,"Compliant") -> 8 | M19: =IF(B19=0,"",L19/B19) -> 0.61538462
A20: V15 – Secure Coding and Architecture | B20: 21 | C20: 3 | D20: =COUNTIFS('V15 - Secure Coding and Archite'!$F$2:$F$26,"Compliant",'V15 - Secure Coding and Archite'!$E$2:$E$26,1) -> 3 | E20: =IF(C20=0,"",D20/C20) -> 1 | F20: 10 | G20: =COUNTIFS('V15 - Secure Coding and Archite'!$F$2:$F$26,"Compliant",'V15 - Secure Coding and Archite'!$E$2:$E$26,2) -> 5 | H20: =IF(F20=0,"",G20/F20) -> 0.5 | I20: 8 | J20: =COUNTIFS('V15 - Secure Coding and Archite'!$F$2:$F$26,"Compliant",'V15 - Secure Coding and Archite'!$E$2:$E$26,3) -> 3 | K20: =IF(I20=0,"",J20/I20) -> 0.375 | L20: =COUNTIF('V15 - Secure Coding and Archite'!$F$2:$F$26,"Compliant") -> 11 | M20: =IF(B20=0,"",L20/B20) -> 0.52380952
A21: V16 – Security Logging and Error Handling | B21: 17 | C21: 0 | D21: =COUNTIFS('V16 - Security Logging and Erro'!E3:E23,"Compliant",'V16 - Security Logging and Erro'!F3:F23,1) -> 0 | E21: =IF(C21=0,"",D21/C21) | F21: 16 | G21: =COUNTIFS('V16 - Security Logging and Erro'!F3:F23,"Compliant",'V16 - Security Logging and Erro'!E3:E23,2) -> 10 | H21: =IF(F21=0,"",G21/F21) -> 0.625 | I21: 1 | J21: =COUNTIFS('V16 - Security Logging and Erro'!F3:F23,"Compliant",'V16 - Security Logging and Erro'!E3:E23,3) -> 0 | K21: =IF(I21=0,"",J21/I21) -> 0 | L21: =COUNTIF('V16 - Security Logging and Erro'!$F$2:$F$23,"Compliant") -> 10 | M21: =IF(B21=0,"",L21/B21) -> 0.58823529
A22: V17 – WebRTC | B22: 12 | C22: 0 | D22: =COUNTIFS('V17 - WebRTC'!E3:E16,"Compliant",'V17 - WebRTC'!F3:F16,1) -> 0 | E22: =IF(C22=0,"",D22/C22) | F22: 7 | G22: =COUNTIFS('V17 - WebRTC'!F3:F16,"Compliant",'V17 - WebRTC'!E3:E16,2) -> 0 | H22: =IF(F22=0,"",G22/F22) -> 0 | I22: 5 | J22: =COUNTIFS('V17 - WebRTC'!F3:F16,"Compliant",'V17 - WebRTC'!E3:E16,3) -> 0 | K22: =IF(I22=0,"",J22/I22) -> 0 | L22: =COUNTIF('V17 - WebRTC'!$F$2:$F$16,"Compliant") -> 0 | M22: =IF(B22=0,"",L22/B22) -> 0
A23: TOTAL | B23: 345 | C23: 70 | D23: =SUM(D6:D22) -> 51 | E23: =IFERROR(AVERAGE(E6:E22),"") -> 0.77153846 | F23: =SUM(F6:F22) -> 183 | G23: =SUM(G6:G22) -> 96 | H23: =IFERROR(AVERAGE(H6:H22),"") -> 0.57747309 | I23: =SUM(I6:I22) -> 92 | J23: =SUM(J6:J22) -> 45 | K23: =IFERROR(AVERAGE(K6:K22),"") -> 0.45885417 | L23: =SUM(L6:L22) -> 192 | M23: =IFERROR(AVERAGE(M6:M22),"") -> 0.60336

Sheet V1 - Encoding and Sanitization
A1: Section ID | B1: Section Name | C1: Req ID | D1: Description | E1: Level | F1: Status | G1: Observations | H1: Reference / Link
A2: V1.1 | B2: Encoding and Sanitization Architecture
A3: V1.1 | B3: Encoding and Sanitization Architecture | C3: V1.1.1 | D3: Verify that input is decoded or unescaped into a canonical form only once, it is only decoded when encoded data in that form is expected, and that this is done before processing the input further, for example it is not performed after input validation or sanitization. | E3: 2 | F3: Compliant | G3: Spring MVC / Jackson decode the HTTP request body into the typed DTO record exactly once. The application performs no manual URL decoding loops or double-decoding of any inbound value. | H3: Spring Boot 3.5 default request pipeline; *Controller.java
A4: V1.1 | B4: Encoding and Sanitization Architecture | C4: V1.1.2 | D4: Verify that the application performs output encoding and escaping either as a final step before being used by the interpreter for which it is intended or by the interpreter itself. | E4: 2 | F4: Compliant | G4: Output JSON is generated by Jackson which encodes/escapes values automatically. Audit-log details are CRLF/control-char-stripped by AuditService.sanitize() before being written. | H4: AuditService.java#sanitize; Spring default ObjectMapper
A5: V1.2 | B5: Injection Prevention
A6: V1.2 | B6: Injection Prevention | C6: V1.2.1 | D6: Verify that output encoding for an HTTP response, HTML document, or XML document is relevant for the context required, such as encoding the relevant characters for HTML elements, HTML attributes, HTML comments, CSS, or HTTP header fields, to avoid changing the message or document structure. | E6: 1 | F6: In Progress | G6: x
A7: V1.2 | B7: Injection Prevention | C7: V1.2.2 | D7: Verify that when dynamically building URLs, untrusted data is encoded according to its context (e.g., URL encoding or base64url encoding for query or path parameters). Ensure that only safe URL protocols are permitted (e.g., disallow javascript: or data:). | E7: 1 | F7: Not Applicable
A8: V1.2 | B8: Injection Prevention | C8: V1.2.3 | D8: Verify that output encoding or escaping is used when dynamically building JavaScript content (including JSON), to avoid changing the message or document structure (to avoid JavaScript and JSON injection). | E8: 1 | F8: Compliant | G8: All responses are JSON serialised by Jackson, which encodes special characters in string values (e.g., quotes, backslashes, control chars). | H8: Spring Boot default Jackson MessageConverter
A9: V1.2 | B9: Injection Prevention | C9: V1.2.4 | D9: Verify that data selection or database queries (e.g., SQL, HQL, NoSQL, Cypher) use parameterized queries, ORMs, entity frameworks, or are otherwise protected from SQL Injection and other database injection attacks. This is also relevant when writing stored procedures. | E9: 1 | F9: Compliant | G9: Persistence goes exclusively through Spring Data JPA repositories with derived methods (findAllByOwnerId, existsByIdAndOwnerId, etc.); there is no native SQL / HQL / JPQL string concatenation anywhere in the codebase. | H9: backend/src/main/java/com/kryptos/**/domain/*Repository.java
A10: V1.2 | B10: Injection Prevention | C10: V1.2.5 | D10: Verify that the application protects against OS command injection and that operating system calls use parameterized OS queries or use contextual command line output encoding. | E10: 1 | F10: Compliant | G10: No OS command invocation exists: there is zero use of Runtime.exec, ProcessBuilder, or Process. All file operations use java.nio.file (Path/Files) and never shell out. | H10: FileHandlingService.java; grep over backend/src/main
A11: V1.2 | B11: Injection Prevention | C11: V1.2.6 | D11: Verify that the application protects against LDAP injection vulnerabilities, or that specific security controls to prevent LDAP injection have been implemented. | E11: 2 | F11: Not Applicable
A12: V1.2 | B12: Injection Prevention | C12: V1.2.7 | D12: Verify that the application is protected against XPath injection attacks by using query parameterization or precompiled queries. | E12: 2 | F12: Not Applicable
A13: V1.2 | B13: Injection Prevention | C13: V1.2.8 | D13: Verify that LaTeX processors are configured securely (such as not using the "--shell-escape" flag) and an allowlist of commands is used to prevent LaTeX injection attacks. | E13: 2 | F13: Not Applicable
A14: V1.2 | B14: Injection Prevention | C14: V1.2.9 | D14: Verify that the application escapes special characters in regular expressions (typically using a backslash) to prevent them from being misinterpreted as metacharacters. | E14: 2 | F14: Compliant | G14: The only regex literals in the codebase are static and non-user-controlled: [\\x00-\\x1F\\x7F] (sanitization), [A-Za-z0-9]{1,8} (extension allowlist). No regex is composed with user input. | H14: AuditService.sanitize; CredentialImportExportService.safe; FileHandlingService.storeUpload
A15: V1.2 | B15: Injection Prevention | C15: V1.2.10 | D15: Verify that the application is protected against CSV and Formula Injection. The application must follow the escaping rules defined in RFC 4180 sections 2.6 and 2.7 when exporting CSV content. Additionally, when exporting to CSV or other spreadsheet formats (such as XLS, XLSX, or ODF), special characters (including '=', '+', '-', '@', '\t' (tab), and '\0' (null character)) must be escaped with a single quote if they appear as the first character in a field value. | E15: 3 | F15: Not Applicable
A16: V1.3 | B16: Sanitization
A17: V1.3 | B17: Sanitization | C17: V1.3.1 | D17: Verify that all untrusted HTML input from WYSIWYG editors or similar is sanitized using a well-known and secure HTML sanitization library or framework feature. | E17: 1 | F17: Not Applicable
A18: V1.3 | B18: Sanitization | C18: V1.3.2 | D18: Verify that the application avoids the use of eval() or other dynamic code execution features such as Spring Expression Language (SpEL). Where there is no alternative, any user input being included must be sanitized before being executed. | E18: 1 | F18: Compliant | G18: No use of Spring Expression Language with user input. @PreAuthorize expressions are literal strings ("hasRole('USER')" etc.). No reflection-based code execution. | H18: All @PreAuthorize sites in backend/src/main/java/com/kryptos/**/api/
A19: V1.3 | B19: Sanitization | C19: V1.3.3 | D19: Verify that data being passed to a potentially dangerous context is sanitized beforehand to enforce safety measures, such as only allowing characters which are safe for this context and trimming input which is too long. | E19: 2 | F19: Compliant | G19: AuditService.sanitize strips control characters and CRLF before persistence; CredentialImportExportService.safe truncates and strips control chars before writing imported strings to JPA. | H19: AuditService.sanitize; CredentialImportExportService.safe; AuditServiceTest.log_shouldSanitizeDetails
A20: V1.3 | B20: Sanitization | C20: V1.3.4 | D20: Verify that user-supplied Scalable Vector Graphics (SVG) scriptable content is validated or sanitized to contain only tags and attributes (such as draw graphics) that are safe for the application, e.g., do not contain scripts and foreignObject. | E20: 2 | F20: Not Applicable
A21: V1.3 | B21: Sanitization | C21: V1.3.5 | D21: Verify that the application sanitizes or disables user-supplied scriptable or expression template language content, such as Markdown, CSS or XSL stylesheets, BBCode, or similar. | E21: 2 | F21: Not Applicable
A22: V1.3 | B22: Sanitization | C22: V1.3.6 | D22: Verify that the application protects against Server-side Request Forgery (SSRF) attacks, by validating untrusted data against an allowlist of protocols, domains, paths and ports and sanitizing potentially dangerous characters before using the data to call another service. | E22: 2 | F22: Compliant | G22: Kryptos performs no outbound HTTP/URL fetches based on user-supplied data. The application has zero SSRF surface: no HTTP client is instantiated with a user-controlled URL, no URL fields exist in any DTO that are dereferenced server-side. | H22: No RestTemplate / WebClient / HttpClient usage anywhere in backend/src/main/java
A23: V1.3 | B23: Sanitization | C23: V1.3.7 | D23: Verify that the application protects against template injection attacks by not allowing templates to be built based on untrusted input. Where there is no alternative, any untrusted input being included dynamically during template creation must be sanitized or strictly validated. | E23: 2 | F23: Compliant | G23: Kryptos has no template engine. There is no Thymeleaf, Freemarker, Velocity, Mustache, or any other templating library declared in pom.xml. Responses are JSON, generated by Jackson. | H23: backend/pom.xml (no template engine dependencies)
A24: V1.3 | B24: Sanitization | C24: V1.3.8 | D24: Verify that the application appropriately sanitizes untrusted input before use in Java Naming and Directory Interface (JNDI) queries and that JNDI is configured securely to prevent JNDI injection attacks. | E24: 2 | F24: Compliant | G24: No JNDI lookup paths exist in the codebase. No InitialContext / Context.lookup() calls. Spring Boot is configured with a direct JDBC DataSource (no JNDI DataSource lookup). | H24: application.properties#spring.datasource.url; SecurityConfig.java
A25: V1.3 | B25: Sanitization | C25: V1.3.9 | D25: Verify that the application sanitizes content before it is sent to memcache to prevent injection attacks. | E25: 2 | F25: Not Applicable
A26: V1.3 | B26: Sanitization | C26: V1.3.10 | D26: Verify that format strings which might resolve in an unexpected or malicious way when used are sanitized before being processed. | E26: 2 | F26: Compliant | G26: Java does not expose C-style format-string vulnerabilities (compiler enforces type safety on String.format placeholders). All String.format calls in the codebase use static literal format strings. | H26: AuditService.java; FileHandlingService.java
A27: V1.3 | B27: Sanitization | C27: V1.3.11 | D27: Verify that the application sanitizes user input before passing to mail systems to protect against SMTP or IMAP injection. | E27: 2 | F27: Not Applicable
A28: V1.3 | B28: Sanitization | C28: V1.3.12 | D28: Verify that regular expressions are free from elements causing exponential backtracking, and ensure untrusted input is sanitized to mitigate ReDoS or Runaway Regex attacks. | E28: 3 | F28: Compliant | G28: The two regex literals in use are ReDoS-safe: [\\x00-\\x1F\\x7F] (single character class) and [A-Za-z0-9]{1,8} (bounded, no nested quantifiers, no alternation). User input is matched, never used to build a pattern. | H28: AuditService.sanitize; FileHandlingService.storeUpload
A29: V1.4 | B29: Memory, String, and Unmanaged Code
A30: V1.4 | B30: Memory, String, and Unmanaged Code | C30: V1.4.1 | D30: Verify that the application uses memory-safe string, safer memory copy and pointer arithmetic to detect or prevent stack, buffer, or heap overflows. | E30: 2 | F30: Compliant | G30: Java is a memory-safe language: no pointer arithmetic, no manual buffer management, no JNI / Unsafe usage. The codebase exclusively uses Java collections and java.nio buffers. | H30: Language-level guarantee; backend/src/main
A31: V1.4 | B31: Memory, String, and Unmanaged Code | C31: V1.4.2 | D31: Verify that sign, range, and input validation techniques are used to prevent integer overflows. | E31: 2 | F31: Compliant | G31: DTOs enforce input ranges via @Size on length-bounded fields (username, email, password, vault names). File-size and record-count limits use long arithmetic with explicit bounds (5 MiB cap, 50 000 lines). Java overflow semantics are well defined. | H31: RegisterRequest.java; CreateVaultRequest.java; FileHandlingService.java
A32: V1.4 | B32: Memory, String, and Unmanaged Code | C32: V1.4.3 | D32: Verify that dynamically allocated memory and resources are released, and that references or pointers to freed memory are removed or set to null to prevent dangling pointers and use-after-free vulnerabilities. | E32: 2 | F32: Not Applicable
A33: V1.5 | B33: Safe Deserialization
A34: V1.5 | B34: Safe Deserialization | C34: V1.5.1 | D34: Verify that the application configures XML parsers to use a restrictive configuration and that unsafe features such as resolving external entities are disabled to prevent XML eXternal Entity (XXE) attacks. | E34: 1 | F34: Not Applicable
A35: V1.5 | B35: Safe Deserialization | C35: V1.5.2 | D35: Verify that deserialization of untrusted data enforces safe input handling, such as using an allowlist of object types or restricting client-defined object types, to prevent deserialization attacks. Deserialization mechanisms that are explicitly defined as insecure must not be used with untrusted input. | E35: 2 | F35: Compliant | G35: Jackson deserialisation uses an explicit target type (ObjectMapper.readValue(..., CredentialExportRecord.class)); polymorphic typing is not enabled, so attacker cannot influence the class instantiated. Java built-in serialization is not used anywhere. | H35: CredentialImportExportService.java#importForOwner
A36: V1.5 | B36: Safe Deserialization | C36: V1.5.3 | D36: Verify that different parsers used in the application for the same data type (e.g., JSON parsers, XML parsers, URL parsers), perform parsing in a consistent way and use the same character encoding mechanism to avoid issues such as JSON Interoperability vulnerabilities or different URI or file parsing behavior being exploited in Remote File Inclusion (RFI) or Server-side Request Forgery (SSRF) attacks. | E36: 3 | F36: Compliant | G36: Only one parser (Jackson) is in use for the only structured data format (JSON). There is no XML, YAML, or alternative JSON parser, so parser-divergence vulnerabilities are not exposed. | H36: backend/pom.xml; CredentialImportExportService.java

Sheet V2 - Validation and Business Lo
A1: Section ID | B1: Section Name | C1: Req ID | D1: Description | E1: Level | F1: Status | G1: Observations | H1: Reference / Link
A2: V2.1 | B2: Validation and Business Logic Documentation
A3: V2.1 | B3: Validation and Business Logic Documentation | C3: V2.1.1 | D3: Verify that the application's documentation defines input validation rules for how to check the validity of data items against an expected structure. This could be common data formats such as credit card numbers, email addresses, telephone numbers, or it could be an internal data format. | E3: 1 | F3: Compliant | G3: Applicable to Kryptos due to diverse data inputs (emails, vault names); need to document strict validation rules for every data field.
A4: V2.1 | B4: Validation and Business Logic Documentation | C4: V2.1.2 | D4: Verify that the application's documentation defines how to validate the logical and contextual consistency of combined data items, such as checking that suburb and ZIP code match. | E4: 2 | F4: Compliant | G4: Applicable to Kryptos due to related data entities (User-Vault-Credential); need to document how logical consistency is validated between these objects.
A5: V2.1 | B5: Validation and Business Logic Documentation | C5: V2.1.3 | D5: Verify that expectations for business logic limits and validations are documented, including both per-user and globally across the application. | E5: 2 | F5: Compliant | G5: Applicable to Kryptos due to resource management; need to document global and per-user limits for vaults and credential entries.
A6: V2.2 | B6: Input Validation
A7: V2.2 | B7: Input Validation | C7: V2.2.1 | D7: Verify that input is validated to enforce business or functional expectations for that input. This should either use positive validation against an allow list of values, patterns, and ranges, or be based on comparing the input to an expected structure and logical limits according to predefined rules. For L1, this can focus on input which is used to make specific business or security decisions. For L2 and up, this should apply to all input. | E7: 1 | F7: Compliant | G7: Implemented via DTO bean validation (@NotBlank, @Email, @Size) on every request record and positive validation on file uploads (extension allowlist [A-Za-z0-9]{1,8} and CRLF stripping in CredentialImportExportService.safe()). | H7: backend/src/main/java/com/kryptos/**/dto/*.java; backend/src/main/java/com/kryptos/filehandling/application/FileHandlingService.java#storeUpload; CredentialControllerTest.create_shouldReturn400_whenServiceNameIsBlank
A8: V2.2 | B8: Input Validation | C8: V2.2.2 | D8: Verify that the application is designed to enforce input validation at a trusted service layer. While client-side validation improves usability and should be encouraged, it must not be relied upon as a security control. | E8: 1 | F8: Compliant | G8: All validation lives in the backend service/controller layer; there is no frontend in scope and no validation is delegated to the client. DTOs are validated via @Valid in controllers; ownership and business invariants are enforced in services. | H8: backend/src/main/java/com/kryptos/**/api/*Controller.java; backend/src/main/java/com/kryptos/**/application/*Service.java
A9: V2.2 | B9: Input Validation | C9: V2.2.3 | D9: Verify that the application ensures that combinations of related data items are reasonable according to the pre-defined rules. | E9: 2 | F9: Compliant | G9: Composite consistency checks: CredentialService.create validates vault ownership before saving (vaultRepository.existsByIdAndOwnerId); TrustedDeviceService.register rejects fingerprints already bound to another user. | H9: backend/src/main/java/com/kryptos/credential/application/CredentialService.java; backend/src/main/java/com/kryptos/trusteddevice/application/TrustedDeviceService.java
A10: V2.3 | B10: Business Logic Security
A11: V2.3 | B11: Business Logic Security | C11: V2.3.1 | D11: Verify that the application will only process business logic flows for the same user in the expected sequential step order and without skipping steps. | E11: 1 | F11: Compliant | G11: Kryptos exposes a stateless REST API; every authenticated request is independently authorized via @PreAuthorize and ownership checks. There are no multi-step server-side flows whose sequence could be bypassed, so step-skipping is not exploitable. | H11: All controllers under backend/src/main/java/com/kryptos/**/api/
A12: V2.3 | B12: Business Logic Security | C12: V2.3.2 | D12: Verify that business logic limits are implemented per the application's documentation to avoid business logic flaws being exploited. | E12: 2 | F12: Compliant | G12: Business-logic limits are implemented in code (5 login attempts → 15 min lockout, 5 imports/min/principal, 5 exports/min/principal, 5 MiB file cap, 50 000 line cap). Formal documentation of these limits is still pending. | H12: backend/src/main/java/com/kryptos/auth/application/AuthService.java; backend/src/main/java/com/kryptos/filehandling/application/ImportExportRateLimiter.java; backend/src/main/java/com/kryptos/filehandling/application/FileHandlingService.java
A13: V2.3 | B13: Business Logic Security | C13: V2.3.3 | D13: Verify that transactions are being used at the business logic level such that either a business logic operation succeeds in its entirety or it is rolled back to the previous correct state. | E13: 2 | F13: Compliant | G13: Every mutating service method is annotated @Transactional, so a partial failure rolls back the operation (e.g., CredentialService.create, VaultService.delete, AuditService.log, CredentialImportExportService.importForOwner). | H13: backend/src/main/java/com/kryptos/**/application/*Service.java
A14: V2.3 | B14: Business Logic Security | C14: V2.3.4 | D14: Verify that business logic level locking mechanisms are used to ensure that limited quantity resources (such as theater seats or delivery slots) cannot be double-booked by manipulating the application's logic. | E14: 2 | F14: Not Applicable
A15: V2.3 | B15: Business Logic Security | C15: V2.3.5 | D15: Verify that high-value business logic flows require multi-user approval to prevent unauthorized or accidental actions. This could include but is not limited to large monetary transfers, contract approvals, access to classified information, or safety overrides in manufacturing. | E15: 3 | F15: Not Applicable
A16: V2.4 | B16: Anti-automation
A17: V2.4 | B17: Anti-automation | C17: V2.4.1 | D17: Verify that anti-automation controls are in place to protect against excessive calls to application functions that could lead to data exfiltration, garbage-data creation, quota exhaustion, rate-limit breaches, denial-of-service, or overuse of costly resources. | E17: 2 | F17: Compliant | G17: Anti-automation: login endpoint enforces 5 attempts/min/principal with a 15 min lockout (AuthService); import/export endpoints enforce 5 requests/min/principal via ImportExportRateLimiter → HTTP 429. | H17: AuthService.java; ImportExportRateLimiter.java; AuthServiceTest.login_shouldLockAccount_afterMaxFailedAttempts; ImportExportRateLimiterTest.tryAcquireExport_allowsFivePerMinute_thenThrottles
A18: V2.4 | B18: Anti-automation | C18: V2.4.2 | D18: Verify that business logic flows require realistic human timing, preventing excessively rapid transaction submissions. | E18: 3 | F18: Compliant | G18: Anti-automation realised through ImportExportRateLimiter (5 req/min/principal on import and export) and AuthService (5 login attempts/min/principal → 15 min lockout). Both implement the "no rapid submissions" intent of the requirement. | H18: AuthService.java; ImportExportRateLimiter.java; ImportExportRateLimiterTest

Sheet V3 - Web Frontend Security
A1: Section ID | B1: Section Name | C1: Req ID | D1: Description | E1: Level | F1: Status | G1: Observations | H1: Reference / Link
A2: V3.1 | B2: Web Frontend Security Documentation
A3: V3.1 | B3: Web Frontend Security Documentation | C3: V3.1.1 | D3: Verify that application documentation states the expected security features that browsers using the application must support (such as HTTPS, HTTP Strict Transport Security (HSTS), Content Security Policy (CSP), and other relevant HTTP security mechanisms). It must also define how the application must behave when some of these features are not available (such as warning the user or blocking access). | E3: 3 | F3: Not Applicable
A4: V3.2 | B4: Unintended Content Interpretation
A5: V3.2 | B5: Unintended Content Interpretation | C5: V3.2.1 | D5: Verify that security controls are in place to prevent browsers from rendering content or functionality in HTTP responses in an incorrect context (e.g., when an API, a user-uploaded file or other resource is requested directly). Possible controls could include: not serving the content unless HTTP request header fields (such as Sec-Fetch-\*) indicate it is the correct context, using the sandbox directive of the Content-Security-Policy header field or using the attachment disposition type in the Content-Disposition header field. | E5: 1 | F5: Not Applicable
A6: V3.2 | B6: Unintended Content Interpretation | C6: V3.2.2 | D6: Verify that content intended to be displayed as text, rather than rendered as HTML, is handled using safe rendering functions (such as createTextNode or textContent) to prevent unintended execution of content such as HTML or JavaScript. | E6: 1 | F6: Not Applicable
A7: V3.2 | B7: Unintended Content Interpretation | C7: V3.2.3 | D7: Verify that the application avoids DOM clobbering when using client-side JavaScript by employing explicit variable declarations, performing strict type checking, avoiding storing global variables on the document object, and implementing namespace isolation. | E7: 3 | F7: Not Applicable
A8: V3.3 | B8: Cookie Setup
A9: V3.3 | B9: Cookie Setup | C9: V3.3.1 | D9: Verify that cookies have the 'Secure' attribute set, and if the '\__Host-' prefix is not used for the cookie name, the '__Secure-' prefix must be used for the cookie name. | E9: 1 | F9: Not Applicable
A10: V3.3 | B10: Cookie Setup | C10: V3.3.2 | D10: Verify that each cookie's 'SameSite' attribute value is set according to the purpose of the cookie, to limit exposure to user interface redress attacks and browser-based request forgery attacks, commonly known as cross-site request forgery (CSRF). | E10: 2 | F10: Not Applicable
A11: V3.3 | B11: Cookie Setup | C11: V3.3.3 | D11: Verify that cookies have the '__Host-' prefix for the cookie name unless they are explicitly designed to be shared with other hosts. | E11: 2 | F11: Not Applicable
A12: V3.3 | B12: Cookie Setup | C12: V3.3.4 | D12: Verify that if the value of a cookie is not meant to be accessible to client-side scripts (such as a session token), the cookie must have the 'HttpOnly' attribute set and the same value (e. g. session token) must only be transferred to the client via the 'Set-Cookie' header field. | E12: 2 | F12: Not Applicable
A13: V3.3 | B13: Cookie Setup | C13: V3.3.5 | D13: Verify that when the application writes a cookie, the cookie name and value length combined are not over 4096 bytes. Overly large cookies will not be stored by the browser and therefore not sent with requests, preventing the user from using application functionality which relies on that cookie. | E13: 3 | F13: Not Applicable
A14: V3.4 | B14: Browser Security Mechanism Headers
A15: V3.4 | B15: Browser Security Mechanism Headers | C15: V3.4.1 | D15: Verify that a Strict-Transport-Security header field is included on all responses to enforce an HTTP Strict Transport Security (HSTS) policy. A maximum age of at least 1 year must be defined, and for L2 and up, the policy must apply to all subdomains as well. | E15: 1 | F15: Not Applicable
A16: V3.4 | B16: Browser Security Mechanism Headers | C16: V3.4.2 | D16: Verify that the Cross-Origin Resource Sharing (CORS) Access-Control-Allow-Origin header field is a fixed value by the application, or if the Origin HTTP request header field value is used, it is validated against an allowlist of trusted origins. When 'Access-Control-Allow-Origin: *' needs to be used, verify that the response does not include any sensitive information. | E16: 1 | F16: Not Applicable
A17: V3.4 | B17: Browser Security Mechanism Headers | C17: V3.4.3 | D17: Verify that HTTP responses include a Content-Security-Policy response header field which defines directives to ensure the browser only loads and executes trusted content or resources, in order to limit execution of malicious JavaScript. As a minimum, a global policy must be used which includes the directives object-src 'none' and base-uri 'none' and defines either an allowlist or uses nonces or hashes. For an L3 application, a per-response policy with nonces or hashes must be defined. | E17: 2 | F17: Not Applicable
A18: V3.4 | B18: Browser Security Mechanism Headers | C18: V3.4.4 | D18: Verify that all HTTP responses contain an 'X-Content-Type-Options: nosniff' header field. This instructs browsers not to use content sniffing and MIME type guessing for the given response, and to require the response's Content-Type header field value to match the destination resource. For example, the response to a request for a style is only accepted if the response's Content-Type is 'text/css'. This also enables the use of the Cross-Origin Read Blocking (CORB) functionality by the browser. | E18: 2 | F18: Not Applicable
A19: V3.4 | B19: Browser Security Mechanism Headers | C19: V3.4.5 | D19: Verify that the application sets a referrer policy to prevent leakage of technically sensitive data to third-party services via the 'Referer' HTTP request header field. This can be done using the Referrer-Policy HTTP response header field or via HTML element attributes. Sensitive data could include path and query data in the URL, and for internal non-public applications also the hostname. | E19: 2 | F19: Not Applicable
A20: V3.4 | B20: Browser Security Mechanism Headers | C20: V3.4.6 | D20: Verify that the web application uses the frame-ancestors directive of the Content-Security-Policy header field for every HTTP response to ensure that it cannot be embedded by default and that embedding of specific resources is allowed only when necessary. Note that the X-Frame-Options header field, although supported by browsers, is obsolete and may not be relied upon. | E20: 2 | F20: Not Applicable
A21: V3.4 | B21: Browser Security Mechanism Headers | C21: V3.4.7 | D21: Verify that the Content-Security-Policy header field specifies a location to report violations. | E21: 3 | F21: Not Applicable
A22: V3.4 | B22: Browser Security Mechanism Headers | C22: V3.4.8 | D22: Verify that all HTTP responses that initiate a document rendering (such as responses with Content-Type text/html), include the Cross‑Origin‑Opener‑Policy header field with the same-origin directive or the same-origin-allow-popups directive as required. This prevents attacks that abuse shared access to Window objects, such as tabnabbing and frame counting. | E22: 3 | F22: Not Applicable
A23: V3.5 | B23: Browser Origin Separation
A24: V3.5 | B24: Browser Origin Separation | C24: V3.5.1 | D24: Verify that, if the application does not rely on the CORS preflight mechanism to prevent disallowed cross-origin requests to use sensitive functionality, these requests are validated to ensure they originate from the application itself. This may be done by using and validating anti-forgery tokens or requiring extra HTTP header fields that are not CORS-safelisted request-header fields. This is to defend against browser-based request forgery attacks, commonly known as cross-site request forgery (CSRF). | E24: 1 | F24: Not Applicable
A25: V3.5 | B25: Browser Origin Separation | C25: V3.5.2 | D25: Verify that, if the application relies on the CORS preflight mechanism to prevent disallowed cross-origin use of sensitive functionality, it is not possible to call the functionality with a request which does not trigger a CORS-preflight request. This may require checking the values of the 'Origin' and 'Content-Type' request header fields or using an extra header field that is not a CORS-safelisted header-field. | E25: 1 | F25: Not Applicable
A26: V3.5 | B26: Browser Origin Separation | C26: V3.5.3 | D26: Verify that HTTP requests to sensitive functionality use appropriate HTTP methods such as POST, PUT, PATCH, or DELETE, and not methods defined by the HTTP specification as "safe" such as HEAD, OPTIONS, or GET. Alternatively, strict validation of the Sec-Fetch-* request header fields can be used to ensure that the request did not originate from an inappropriate cross-origin call, a navigation request, or a resource load (such as an image source) where this is not expected. | E26: 1 | F26: Not Applicable
A27: V3.5 | B27: Browser Origin Separation | C27: V3.5.4 | D27: Verify that separate applications are hosted on different hostnames to leverage the restrictions provided by same-origin policy, including how documents or scripts loaded by one origin can interact with resources from another origin and hostname-based restrictions on cookies. | E27: 2 | F27: Not Applicable
A28: V3.5 | B28: Browser Origin Separation | C28: V3.5.5 | D28: Verify that messages received by the postMessage interface are discarded if the origin of the message is not trusted, or if the syntax of the message is invalid. | E28: 2 | F28: Not Applicable
A29: V3.5 | B29: Browser Origin Separation | C29: V3.5.6 | D29: Verify that JSONP functionality is not enabled anywhere across the application to avoid Cross-Site Script Inclusion (XSSI) attacks. | E29: 3 | F29: Not Applicable
A30: V3.5 | B30: Browser Origin Separation | C30: V3.5.7 | D30: Verify that data requiring authorization is not included in script resource responses, like JavaScript files, to prevent Cross-Site Script Inclusion (XSSI) attacks. | E30: 3 | F30: Not Applicable
A31: V3.5 | B31: Browser Origin Separation | C31: V3.5.8 | D31: Verify that authenticated resources (such as images, videos, scripts, and other documents) can be loaded or embedded on behalf of the user only when intended. This can be accomplished by strict validation of the Sec-Fetch-* HTTP request header fields to ensure that the request did not originate from an inappropriate cross-origin call, or by setting a restrictive Cross-Origin-Resource-Policy HTTP response header field to instruct the browser to block returned content. | E31: 3 | F31: Not Applicable
A32: V3.6 | B32: External Resource Integrity
A33: V3.6 | B33: External Resource Integrity | C33: V3.6.1 | D33: Verify that client-side assets, such as JavaScript libraries, CSS, or web fonts, are only hosted externally (e.g., on a Content Delivery Network) if the resource is static and versioned and Subresource Integrity (SRI) is used to validate the integrity of the asset. If this is not possible, there should be a documented security decision to justify this for each resource. | E33: 3 | F33: Not Applicable
A34: V3.7 | B34: Other Browser Security Considerations
A35: V3.7 | B35: Other Browser Security Considerations | C35: V3.7.1 | D35: Verify that the application only uses client-side technologies which are still supported and considered secure. Examples of technologies which do not meet this requirement include NSAPI plugins, Flash, Shockwave, ActiveX, Silverlight, NACL, or client-side Java applets. | E35: 2 | F35: Not Applicable
A36: V3.7 | B36: Other Browser Security Considerations | C36: V3.7.2 | D36: Verify that the application will only automatically redirect the user to a different hostname or domain (which is not controlled by the application) where the destination appears on an allowlist. | E36: 2 | F36: Not Applicable
A37: V3.7 | B37: Other Browser Security Considerations | C37: V3.7.3 | D37: Verify that the application shows a notification when the user is being redirected to a URL outside of the application's control, with an option to cancel the navigation. | E37: 3 | F37: Not Applicable
A38: V3.7 | B38: Other Browser Security Considerations | C38: V3.7.4 | D38: Verify that the application's top-level domain (e.g., site.tld) is added to the public preload list for HTTP Strict Transport Security (HSTS). This ensures that the use of TLS for the application is built directly into the main browsers, rather than relying only on the Strict-Transport-Security response header field. | E38: 3 | F38: Not Applicable
A39: V3.7 | B39: Other Browser Security Considerations | C39: V3.7.5 | D39: Verify that the application behaves as documented (such as warning the user or blocking access) if the browser used to access the application does not support the expected security features. | E39: 3 | F39: Not Applicable

Sheet V4 - API and Web Service
A1: Section ID | B1: Section Name | C1: Req ID | D1: Description | E1: Level | F1: Status | G1: Observations | H1: Reference / Link
A2: V4.1 | B2: Generic Web Service Security
A3: V4.1 | B3: Generic Web Service Security | C3: V4.1.1 | D3: Verify that every HTTP response with a message body contains a Content-Type header field that matches the actual content of the response, including the charset parameter to specify safe character encoding (e.g., UTF-8, ISO-8859-1) according to IANA Media Types, such as "text/", "/+xml" and "/xml". | E3: 1 | F3: Compliant | G3: Spring Boot defaults to application/json;charset=UTF-8 on JSON responses; the export endpoint explicitly sets Content-Type=application/octet-stream with a Content-Disposition header and X-Content-Type-Options=nosniff. | H3: backend/src/main/java/com/kryptos/filehandling/api/ImportExportController.java#exportCredentials
A4: V4.1 | B4: Generic Web Service Security | C4: V4.1.2 | D4: Verify that only user-facing endpoints (intended for manual web-browser access) automatically redirect from HTTP to HTTPS, while other services or endpoints do not implement transparent redirects. This is to avoid a situation where a client is erroneously sending unencrypted HTTP requests, but since the requests are being automatically redirected to HTTPS, the leakage of sensitive data goes undiscovered. | E4: 2 | F4: Not Applicable
A5: V4.1 | B5: Generic Web Service Security | C5: V4.1.3 | D5: Verify that any HTTP header field used by the application and set by an intermediary layer, such as a load balancer, a web proxy, or a backend-for-frontend service, cannot be overridden by the end-user. Example headers might include X-Real-IP, X-Forwarded-*, or X-User-ID. | E5: 2 | F5: Compliant | G5: The application reads identity exclusively from @AuthenticationPrincipal (set by JwtAuthFilter after verifying the Authorization Bearer token). It does not read X-Forwarded-User / X-User-Id / X-Real-IP or any intermediary-set identity header. Spring Boot default server.forward-headers-strategy is NONE. | H5: JwtAuthFilter.java; SecurityConfig.java; all controllers
A6: V4.1 | B6: Generic Web Service Security | C6: V4.1.4 | D6: Verify that only HTTP methods that are explicitly supported by the application or its API (including OPTIONS during preflight requests) can be used and that unused methods are blocked. | E6: 3 | F6: Compliant | G6: Spring MVC returns 405 by default for HTTP methods that are not mapped, and the only mapped methods per endpoint are explicit (POST/GET/PUT/DELETE/PATCH). An explicit method allowlist filter is not in place. | H6: backend/src/main/java/com/kryptos/**/api/*Controller.java
A7: V4.1 | B7: Generic Web Service Security | C7: V4.1.5 | D7: Verify that per-message digital signatures are used to provide additional assurance on top of transport protections for requests or transactions which are highly sensitive or which traverse a number of systems. | E7: 3 | F7: Compliant | G7: Applicable to Kryptos due to HTTP header management; need to ensure that user input cannot manipulate or override security-relevant response headers.
A8: V4.2 | B8: HTTP Message Structure Validation
A9: V4.2 | B9: HTTP Message Structure Validation | C9: V4.2.1 | D9: Verify that all application components (including load balancers, firewalls, and application servers) determine boundaries of incoming HTTP messages using the appropriate mechanism for the HTTP version to prevent HTTP request smuggling. In HTTP/1.x, if a Transfer-Encoding header field is present, the Content-Length header must be ignored per RFC 2616. When using HTTP/2 or HTTP/3, if a Content-Length header field is present, the receiver must ensure that it is consistent with the length of the DATA frames. | E9: 2 | F9: Compliant | G9: HTTP message boundary parsing is delegated to the Spring Boot embedded Tomcat connector, which correctly handles Content-Length and Transfer-Encoding per RFC 7230 and rejects ambiguous messages by default. | H9: Spring Boot 3.5 embedded Tomcat defaults
A10: V4.2 | B10: HTTP Message Structure Validation | C10: V4.2.2 | D10: Verify that when generating HTTP messages, the Content-Length header field does not conflict with the length of the content as determined by the framing of the HTTP protocol, in order to prevent request smuggling attacks. | E10: 3 | F10: Compliant | G10: Responses are produced by Spring MVC; Content-Length is set automatically to match the serialized body length. No manual Content-Length writes anywhere in the code. | H10: Spring MVC default ResponseBodyEmitter / HttpMessageConverter behaviour
A11: V4.2 | B11: HTTP Message Structure Validation | C11: V4.2.3 | D11: Verify that the application does not send nor accept HTTP/2 or HTTP/3 messages with connection-specific header fields such as Transfer-Encoding to prevent response splitting and header injection attacks. | E11: 3 | F11: Compliant | G11: Tomcat HTTP/2 connector rejects connection-specific header fields per RFC 7540 §8.1.2.2 by default. Application does not synthesise such headers anywhere. | H11: Embedded Tomcat HTTP/2 defaults
A12: V4.2 | B12: HTTP Message Structure Validation | C12: V4.2.4 | D12: Verify that the application only accepts HTTP/2 and HTTP/3 requests where the header fields and values do not contain any CR (\r), LF (\n), or CRLF (\r\n) sequences, to prevent header injection attacks. | E12: 3 | F12: Compliant | G12: CR / LF in header names or values are rejected by Tomcat at the HTTP-parser level. Application does not assemble headers from user input — the only response headers come from controller code with static names + bounded values (Content-Type, Content-Disposition, Cache-Control, X-Content-Type-Options). | H12: ImportExportController.exportCredentials; SecurityConfig.headers(...)
A13: V4.2 | B13: HTTP Message Structure Validation | C13: V4.2.5 | D13: Verify that, if the application (backend or frontend) builds and sends requests, it uses validation, sanitization, or other mechanisms to avoid creating URIs (such as for API calls) or HTTP request header fields (such as Authorization or Cookie), which are too long to be accepted by the receiving component. This could cause a denial of service, such as when sending an overly long request (e.g., a long cookie header field), which results in the server always responding with an error status. | E13: 3 | F13: Compliant | G13: The backend does not build or send outbound HTTP requests on behalf of users. There is no RestTemplate / WebClient / HttpClient usage, so URI- or header-injection on outbound calls is not reachable. | H13: No outbound HTTP client in backend/src/main/java
A14: V4.3 | B14: GraphQL
A15: V4.3 | B15: GraphQL | C15: V4.3.1 | D15: Verify that a query allowlist, depth limiting, amount limiting, or query cost analysis is used to prevent GraphQL or data layer expression Denial of Service (DoS) as a result of expensive, nested queries. | E15: 2 | F15: Not Applicable
A16: V4.3 | B16: GraphQL | C16: V4.3.2 | D16: Verify that GraphQL introspection queries are disabled in the production environment unless the GraphQL API is meant to be used by other parties. | E16: 2 | F16: Not Applicable
A17: V4.4 | B17: WebSocket
A18: V4.4 | B18: WebSocket | C18: V4.4.1 | D18: Verify that WebSocket over TLS (WSS) is used for all WebSocket connections. | E18: 1 | F18: Not Applicable
A19: V4.4 | B19: WebSocket | C19: V4.4.2 | D19: Verify that, during the initial HTTP WebSocket handshake, the Origin header field is checked against a list of origins allowed for the application. | E19: 2 | F19: Not Applicable
A20: V4.4 | B20: WebSocket | C20: V4.4.3 | D20: Verify that, if the application's standard session management cannot be used, dedicated tokens are being used for this, which comply with the relevant Session Management security requirements. | E20: 2 | F20: Not Applicable
A21: V4.4 | B21: WebSocket | C21: V4.4.4 | D21: Verify that dedicated WebSocket session management tokens are initially obtained or validated through the previously authenticated HTTPS session when transitioning an existing HTTPS session to a WebSocket channel. | E21: 2 | F21: Not Applicable

Sheet V5 - File Handling
A1: Section ID | B1: Section Name | C1: Req ID | D1: Description | E1: Level | F1: Status | G1: Observations | H1: Reference / Link
A2: V5.1 | B2: File Handling Documentation
A3: V5.1 | B3: File Handling Documentation | C3: V5.1.1 | D3: Verify that the documentation defines the permitted file types, expected file extensions, and maximum size (including unpacked size) for each upload feature. Additionally, ensure that the documentation specifies how files are made safe for end-users to download and process, such as how the application behaves when a malicious file is detected. | E3: 2 | F3: Compliant | G3: Limits exist in code (5 MiB upload cap → 413, 50 000 line record cap, extension allowlist [A-Za-z0-9]{1,8}, 0600 file perms). A formal upload-feature documentation matrix is still pending. | H3: FileHandlingService.java; ImportExportController.java
A4: V5.2 | B4: File Upload and Content
A5: V5.2 | B5: File Upload and Content | C5: V5.2.1 | D5: Verify that the application will only accept files of a size which it can process without causing a loss of performance or a denial of service attack. | E5: 1 | F5: Compliant | G5: 5 MiB cap enforced both at controller (HTTP 413) and at FileHandlingService.storeUpload; importCredentials caps records at 50 000 lines. | H5: ImportExportController.java#importCredentials (HTTP 413 branch); FileHandlingServiceTest.storeUpload_shouldRejectOversizeFile
A6: V5.2 | B6: File Upload and Content | C6: V5.2.2 | D6: Verify that when the application accepts a file, either on its own or within an archive such as a zip file, it checks if the file extension matches an expected file extension and validates that the contents correspond to the type represented by the extension. This includes, but is not limited to, checking the initial 'magic bytes', performing image re-writing, and using specialized libraries for file content validation. For L1, this can focus just on files which are used to make specific business or security decisions. For L2 and up, this must apply to all files being accepted. | E6: 1 | F6: Compliant | G6: Extensions are filtered against a conservative allowlist ([A-Za-z0-9]{1,8}, lowercased). Content validity is enforced downstream by decrypting and JSON-parsing each line; malformed lines are skipped (importForOwner). | H6: FileHandlingService.java#storeUpload; CredentialImportExportService.java#importForOwner
A7: V5.2 | B7: File Upload and Content | C7: V5.2.3 | D7: Verify that the application checks compressed files (e.g., zip, gz, docx, odt) against maximum allowed uncompressed size and against maximum number of files before uncompressing the file. | E7: 2 | F7: Compliant | G7: Kryptos accepts only newline-delimited .kvault import files; no compressed archives (zip, gz, tar, etc.) are decompressed. The compression-bomb attack surface is therefore absent. Hard caps remain in place: 5 MiB payload (HTTP 413) and 50 000 lines. | H7: ImportExportController#importCredentials; FileHandlingService#importCredentials
A8: V5.2 | B8: File Upload and Content | C8: V5.2.4 | D8: Verify that a file size quota and maximum number of files per user are enforced to ensure that a single user cannot fill up the storage with too many files, or excessively large files. | E8: 3 | F8: Compliant | G8: Files are never retained per user: every upload is parsed and securely wiped within the same request, every export streams a freshly built temp file that is wiped immediately after the response body is written. ImportExportRateLimiter caps both endpoints at 5 requests/min/principal → 429. | H8: CredentialImportExportService#importForOwner/exportForOwner; FileHandlingService#secureDelete; ImportExportRateLimiter
A9: V5.2 | B9: File Upload and Content | C9: V5.2.5 | D9: Verify that the application does not allow uploading compressed files containing symlinks unless this is specifically required (in which case it will be necessary to enforce an allowlist of the files that can be symlinked to). | E9: 3 | F9: Compliant | G9: Compressed archives are not accepted by any endpoint (see V5.2.3); symlink-in-archive cannot be reached because no decompression is performed. | H9: ImportExportController; FileHandlingService
A10: V5.2 | B10: File Upload and Content | C10: V5.2.6 | D10: Verify that the application rejects uploaded images with a pixel size larger than the maximum allowed, to prevent pixel flood attacks. | E10: 3 | F10: Not Applicable
A11: V5.3 | B11: File Storage
A12: V5.3 | B12: File Storage | C12: V5.3.1 | D12: Verify that files uploaded or generated by untrusted input and stored in a public folder, are not executed as server-side program code when accessed directly with an HTTP request. | E12: 1 | F12: Compliant | G12: Files are written to an isolated temp directory (kryptos.storage.temp-dir, 0700) outside any web-served path. No static-file handler is registered on the temp dir, so uploads cannot be served as program code. | H12: FileHandlingService.java#initTempDir; application.properties#kryptos.storage.temp-dir
A13: V5.3 | B13: File Storage | C13: V5.3.2 | D13: Verify that when the application creates file paths for file operations, instead of user-submitted filenames, it uses internally generated or trusted data, or if user-submitted filenames or file metadata must be used, strict validation and sanitization must be applied. This is to protect against path traversal, local or remote file inclusion (LFI, RFI), and server-side request forgery (SSRF) attacks. | E13: 1 | F13: Compliant | G13: User filenames are never used as paths. Uploads are stored as import-<UUID><sanitised-extension>; exports as export-<UUID>.kvault. Path-traversal protection via verifyWithinTempDir. | H13: FileHandlingService.java; FileHandlingServiceTest.storeUpload_sanitisesFilename
